Workbook

Sheet Sheet1
A1: Annual Examination Result 2025: 8th B GHSS Adina
A2: S.No | B2: Exam Roll No | C2: Admission Number | D2: Name | E2: Father Name | F2: Date of Birth | G2: English | H2: Urdu | I2: Maths | J2: G.Sc | K2: Islamiat | L2: M.Q | M2: H.G | N2: Computer | O2: Drawing | P2: Obtained Marks | Q2: Failed Subjects | R2: Per% | S2: Remarks
A3: 1 | B3: 350 | C3: 7487 | D3: Muhammad Sajjad | E3: Muhammad Siar | F3: 39907 | G3: 10 | H3: 12 | I3: 9 | J3: 9 | K3: 18 | L3: 5 | M3: 5 | N3: 19 | O3: 28 | P3: =SUM(G3:O3) -> 115 | Q3: 7 | R3: =P3/625 -> 0.184 | S3: Failed
A4: 2 | B4: 351 | C4: 7561 | D4: Muhammad Ahmad | E4: Liaqat Ali | F4: 40942 | G4: 44 | H4: 69 | I4: 12 | J4: 37 | K4: 49 | L4: 41 | M4: 49 | N4: 49 | O4: 53 | P4: =SUM(G4:O4) -> 403 | Q4: 1 | R4: =P4/625 -> 0.6448
A5: 3 | B5: 352 | C5: 7565 | D5: Muhammad Imran | E5: Arshad Ali | F5: 40436 | G5: 17 | H5: 41 | I5: 16 | J5: 13 | K5: 28 | L5: 19 | M5: 10 | N5: 25 | O5: 17 | P5: =SUM(G5:O5) -> 186 | Q5: 5 | R5: =P5/625 -> 0.2976
A6: 4 | B6: 353 | C6: 7566 | D6: Khuzaifa Noor Zaman | E6: Noor Zaman | F6: 40240 | G6: 13 | H6: 27 | I6: 17 | J6: 8 | K6: 18 | L6: 10 | M6: 3 | N6: 2 | O6: 21 | P6: =SUM(G6:O6) -> 119 | Q6: 7 | R6: =P6/625 -> 0.1904
A7: 5 | B7: 354 | C7: 7570 | D7: Muhammad Shayan | E7: Sher Nabi Khan | F7: 40858 | G7: 13 | H7: 45 | I7: 19 | J7: 8 | K7: 21 | L7: 24 | M7: 10 | N7: 33 | O7: 26 | P7: =SUM(G7:O7) -> 199 | Q7: 4 | R7: =P7/625 -> 0.3184
A8: 6 | B8: 355 | C8: 7571 | D8: Haseeb Khan | E8: Nasir Khan | F8: 40422 | G8: 14 | H8: 9 | I8: 13 | J8: 5 | K8: 22 | L8: 8 | M8: 2 | N8: 9 | O8: 21 | P8: =SUM(G8:O8) -> 103 | Q8: 8 | R8: =P8/625 -> 0.1648 | S8: Failed
A9: 7 | B9: 356 | C9: 7572 | D9: Abdullah Mujahid | E9: Mujahid | F9: 40617 | G9: 7 | H9: 36 | I9: 11 | J9: 14 | K9: 24 | L9: 9 | M9: 10 | N9: 12 | O9: 16 | P9: =SUM(G9:O9) -> 139 | Q9: 7 | R9: =P9/625 -> 0.2224 | S9: Failed
A10: 8 | B10: 357 | C10: 7573 | D10: Muhammad Haris | E10: Muhammad Siar | F10: 40655 | G10: 54 | H10: 52 | I10: 33 | J10: 69 | K10: 44 | L10: 37 | M10: 52 | N10: 52 | O10: 47 | P10: =SUM(G10:O10) -> 440 | R10: =P10/625 -> 0.704
A11: 9 | B11: 358 | C11: 7576 | D11: Khuzaifa Ahmad | E11: Muhammad Fayaz | F11: 40584 | G11: 70 | H11: 65 | I11: 49 | J11: 71 | K11: 49 | L11: 43 | M11: 66 | N11: 67 | O11: 65 | P11: =SUM(G11:O11) -> 545 | R11: =P11/625 -> 0.872 | S11: First
A12: 10 | B12: 359 | C12: 7579 | D12: Muhammad Ubaid | E12: Zarwali Khan | F12: 40096 | G12: 12 | H12: 20 | I12: 25 | J12: 11 | K12: 24 | L12: 17 | M12: 10 | N12: 23 | O12: 43 | P12: =SUM(G12:O12) -> 185 | Q12: 5 | R12: =P12/625 -> 0.296
A13: 11 | B13: 360 | C13: 7929 | D13: Shayan Khan | E13: Sahib Zada | F13: 40604 | G13: 33 | H13: 64 | I13: 29 | J13: 26 | K13: 38 | L13: 36 | M13: 35 | N13: 46 | O13: 50 | P13: =SUM(G13:O13) -> 357 | R13: =P13/625 -> 0.5712
A14: 12 | B14: 361 | C14: 7581 | D14: Mustafa Jan | E14: Fida Hussain | F14: 39859 | G14: 23 | H14: 36 | I14: 20 | J14: 6 | K14: 34 | L14: 25 | M14: 25 | N14: 35 | O14: 40 | P14: =SUM(G14:O14) -> 244 | Q14: 3 | R14: =P14/625 -> 0.3904
A15: 13 | B15: 362 | C15: 7582 | D15: Muhammad Hamza | E15: Israrullah | F15: 40268 | G15: 8 | H15: 42 | I15: 20 | J15: 7 | K15: 28 | L15: 21 | M15: 14 | N15: 18 | O15: 44 | P15: =SUM(G15:O15) -> 202 | Q15: 5 | R15: =P15/625 -> 0.3232
A16: 14 | B16: 363 | C16: 7583 | D16: Muhammad Sudais | E16: Farhad Ali | F16: 40635 | G16: 15 | H16: 46 | I16: 8 | J16: 7 | K16: 29 | L16: 24 | M16: 33 | N16: 33 | O16: 42 | P16: =SUM(G16:O16) -> 237 | Q16: 3 | R16: =P16/625 -> 0.3792
A17: 15 | B17: 364 | C17: 7584 | D17: Abid Khan | E17: Khalid Khan | F17: 40643 | G17: 22 | H17: 39 | I17: 18 | J17: 5 | K17: 18 | L17: 18 | M17: 7 | N17: 19 | O17: 25 | P17: =SUM(G17:O17) -> 171 | Q17: 5 | R17: =P17/625 -> 0.2736
A18: 16 | B18: 365 | C18: 7587 | D18: Muhammad Sajid | E18: Javed Ali | F18: 40636 | G18: 26 | H18: 51 | I18: 24 | J18: 20 | K18: 30 | L18: 28 | M18: 25 | N18: 34 | O18: 47 | P18: =SUM(G18:O18) -> 285 | Q18: 2 | R18: =P18/625 -> 0.456
A19: 17 | B19: 366 | C19: 7589 | D19: Walid Ahmad | E19: Fazli Yazdan | F19: 41068 | G19: 23 | H19: 37 | I19: 17 | J19: 25 | K19: 31 | L19: 23 | M19: 17 | N19: 38 | O19: 48 | P19: =SUM(G19:O19) -> 259 | Q19: 3 | R19: =P19/625 -> 0.4144
A20: 18 | B20: 367 | C20: 7593 | D20: Muhmmad Aizaz | E20: Gul Wali | F20: 40941 | G20: 25 | H20: 48 | I20: 18 | J20: 20 | K20: 34 | L20: 30 | M20: 34 | N20: 43 | O20: 49 | P20: =SUM(G20:O20) -> 301 | Q20: 2 | R20: =P20/625 -> 0.4816
A21: 19 | B21: 368 | C21: 7599 | D21: Diyan Khan | E21: Abideen Khan | F21: 40634 | G21: 59 | H21: 60 | I21: 30 | J21: 31 | K21: 40 | L21: 37 | M21: 45 | N21: 60 | O21: 61 | P21: =SUM(G21:O21) -> 423 | R21: =P21/625 -> 0.6768
A22: 20 | B22: 369 | C22: 7600 | D22: Shahdil Khan | E22: Zakir Muhammad | F22: 40605 | G22: 22 | H22: 37 | I22: 22 | J22: 37 | K22: 31 | L22: 27 | M22: 17 | N22: 25 | O22: 33 | P22: =SUM(G22:O22) -> 251 | Q22: 3 | R22: =P22/625 -> 0.4016
A23: 21 | B23: 370 | C23: 7601 | D23: Muhammad Khan | E23: Said Khan | F23: 40313 | G23: 21 | H23: 32 | I23: 21 | J23: 8 | K23: 25 | L23: 18 | M23: 7 | N23: 16 | O23: 30 | P23: =SUM(G23:O23) -> 178 | Q23: 5 | R23: =P23/625 -> 0.2848
A24: 22 | B24: 371 | C24: 7602 | D24: Muhammad Farhan | E24: Muhammad Nisar | F24: 40619 | G24: 14 | H24: 26 | I24: 25 | J24: 14 | K24: 20 | L24: 10 | M24: 13 | N24: 10 | O24: 39 | P24: =SUM(G24:O24) -> 171 | Q24: 5 | R24: =P24/625 -> 0.2736
A25: 23 | B25: 372 | C25: 7608 | D25: Muhammad Osama | E25: Azam Khan | F25: 40214 | G25: 12 | H25: 21 | I25: 15 | J25: 7 | K25: 24 | L25: 10 | M25: 14 | N25: 9 | O25: 29 | P25: =SUM(G25:O25) -> 141 | Q25: 7 | R25: =P25/625 -> 0.2256 | S25: Failed
A26: 24 | B26: 373 | C26: 7612 | D26: Aazan Ali | E26: Liaqat Ali | F26: 40760 | G26: 28 | H26: 70 | I26: 37 | J26: 11 | K26: 35 | L26: 31 | M26: 36 | N26: 18 | O26: 54 | P26: =SUM(G26:O26) -> 320 | Q26: 2 | R26: =P26/625 -> 0.512
A27: 25 | B27: 374 | C27: 7616 | D27: Anas Khan | E27: Muhammad Ishtiaq | F27: 39971 | G27: 35 | H27: 67 | I27: 41 | J27: 20 | K27: 39 | L27: 36 | M27: 37 | N27: 48 | O27: 54 | P27: =SUM(G27:O27) -> 377 | Q27: 1 | R27: =P27/625 -> 0.6032
A28: 26 | B28: 375 | C28: 7618 | D28: Talha Hussain | E28: Nazar Hussain | F28: 40239 | G28: 16 | H28: 27 | I28: 24 | J28: 2 | K28: 21 | L28: 11 | M28: 20 | N28: 7 | O28: 12 | P28: =SUM(G28:O28) -> 140 | Q28: 7 | R28: =P28/625 -> 0.224 | S28: Failed
A29: 27 | B29: 376 | C29: 7621 | D29: Muhammad Abu Bakar | E29: Sabz Ali Khan | F29: 40605 | G29: 37 | H29: 52 | I29: 41 | J29: 17 | K29: 37 | L29: 29 | M29: 33 | N29: 38 | O29: 56 | P29: =SUM(G29:O29) -> 340 | Q29: 1 | R29: =P29/625 -> 0.544
A30: 28 | B30: 377 | C30: 7625 | D30: Awwab Athar | E30: Rahat Said | F30: 40895 | G30: 33 | H30: 58 | I30: 42 | J30: 21 | K30: 35 | L30: 42 | M30: 47 | N30: 51 | O30: 61 | P30: =SUM(G30:O30) -> 390 | Q30: 1 | R30: =P30/625 -> 0.624
A31: 29 | B31: 378 | C31: 7627 | D31: Haseeb Ullah | E31: Rahat Ali | F31: 40633 | G31: 33 | H31: 42 | I31: 33 | J31: 10 | K31: 30 | L31: 24 | M31: 20 | N31: 26 | O31: 57 | P31: =SUM(G31:O31) -> 275 | Q31: 2 | R31: =P31/625 -> 0.44
A32: 30 | B32: 379 | C32: 7628 | D32: Muhammad Atif | E32: Ziaullah | F32: 40565 | G32: 17 | H32: 33 | I32: 17 | J32: 12 | K32: 18 | L32: 18 | M32: 6 | N32: 11 | O32: 43 | P32: =SUM(G32:O32) -> 175 | Q32: 5 | R32: =P32/625 -> 0.28
A33: 31 | B33: 380 | C33: 7636 | D33: Muhammad Zakarya | E33: Shah Hussain | F33: 39887 | G33: 25 | H33: 63 | I33: 34 | J33: 25 | K33: 31 | L33: 29 | M33: 38 | N33: 30 | O33: 55 | P33: =SUM(G33:O33) -> 330 | R33: =P33/625 -> 0.528
A34: 32 | B34: 381 | C34: 7641 | D34: Abdul Subhan | E34: Abdus Salam | F34: 40428 | G34: 15 | H34: 32 | I34: 20 | J34: 8 | K34: 28 | L34: 22 | M34: 20 | N34: 8 | O34: 31 | P34: =SUM(G34:O34) -> 184 | Q34: 5 | R34: =P34/625 -> 0.2944
A35: 33 | B35: 382 | C35: 7648 | D35: Muhammad Aaqib | E35: Ameer Wahid | F35: 40633 | G35: 55 | H35: 69 | I35: 47 | J35: 65 | K35: 38 | L35: 40 | M35: 63 | N35: 59 | O35: 60 | P35: =SUM(G35:O35) -> 496 | R35: =P35/625 -> 0.7936 | S35: Third
A36: 34 | B36: 383 | C36: 7660 | D36: Muhammad Khuzaifa | E36: Hafiz Asad Ali | F36: 40649 | G36: 26 | H36: 39 | I36: 32 | J36: 33 | K36: 31 | L36: 26 | M36: 30 | N36: 37 | O36: 60 | P36: =SUM(G36:O36) -> 314 | R36: =P36/625 -> 0.5024
A37: 35 | B37: 384 | C37: 7662 | D37: Muhammad Abuzar | E37: Ameer Ul Haq | F37: 40969 | G37: 19 | H37: 31 | I37: 17 | J37: 30 | K37: 27 | L37: 27 | M37: 15 | N37: 18 | O37: 34 | P37: =SUM(G37:O37) -> 218 | Q37: 4 | R37: =P37/625 -> 0.3488
A38: 36 | B38: 385 | C38: 7512 | D38: Muhammad Sudais | E38: Nazar Hussain | F38: 40579 | G38: 15 | H38: 40 | I38: 31 | J38: 28 | K38: 18 | L38: 20 | M38: 11 | N38: 33 | O38: 25 | P38: =SUM(G38:O38) -> 221 | Q38: 2 | R38: =P38/625 -> 0.3536
A39: 37 | B39: 386 | C39: 7769 | D39: Adnan Ali | E39: Safdar Ali | F39: 40612 | G39: 19 | H39: 13 | I39: 13 | J39: 25 | K39: 26 | L39: 18 | M39: 3 | N39: 11 | O39: 25 | P39: =SUM(G39:O39) -> 153 | Q39: 5 | R39: =P39/625 -> 0.2448
A40: 38 | B40: 387 | C40: 7772 | D40: Mehran Khan | E40: Saifoor Rahman | F40: 40978 | G40: 33 | H40: 58 | I40: 26 | J40: 17 | K40: 33 | L40: 34 | M40: 34 | N40: 44 | O40: 52 | P40: =SUM(G40:O40) -> 331 | Q40: 1 | R40: =P40/625 -> 0.5296
...

Sheet Position
A2: Position
A3: =RANK(Sheet1!P3,Sheet1!$P$3:$P$54) -> 51
A4: =RANK(Sheet1!P4,Sheet1!$P$3:$P$54) -> 6
A5: =RANK(Sheet1!P5,Sheet1!$P$3:$P$54) -> 32
A6: =RANK(Sheet1!P6,Sheet1!$P$3:$P$54) -> 50
A7: =RANK(Sheet1!P7,Sheet1!$P$3:$P$54) -> 30
A8: =RANK(Sheet1!P8,Sheet1!$P$3:$P$54) -> 52
A9: =RANK(Sheet1!P9,Sheet1!$P$3:$P$54) -> 48
A10: =RANK(Sheet1!P10,Sheet1!$P$3:$P$54) -> 4
A11: =RANK(Sheet1!P11,Sheet1!$P$3:$P$54) -> 1
A12: =RANK(Sheet1!P12,Sheet1!$P$3:$P$54) -> 33
A13: =RANK(Sheet1!P13,Sheet1!$P$3:$P$54) -> 9
A14: =RANK(Sheet1!P14,Sheet1!$P$3:$P$54) -> 24
... A54: =RANK(Sheet1!P54,Sheet1!$P$3:$P$54) -> 2

Sheet Pashto
A2: Pashto
A3: 12
A4: 59
A5: A
A6: 25
A7: 38
A8: 21
A9: 25
A10: 55
A11: 54
A12: 19
A13: 46
A14: 28
A15: 41
A16: 62
A17: 39
... A32: 10
A33: A
A34: 7
A35: 57
A36: 62
A37: 17
A38: 12
A39: 21
A40: 46
A41: 36
A42: 26
A43: 11
A44: 25
A45: 28
... A47: 27
A48: A
A49: 26
A50: 25
A51: 34
A52: 7
A53: 27
A54: 65
